Workbook

Sheet Product Backlog
A1: Product Backlog priorizado · Plataforma de Tutorías entre Estudiantes
A2: Orden de prioridad propuesto el 27-09-2026 · horas y requisitos del Pilar 4 v1.6 · sprints y dueños de la replanificación del 25-09, a acordar con el equipo
A3: Horas del backlog | C3: =SUM(J6:J42) -> 355 | D3: Horas listas | E3: =SUMIFS(J6:J42,L6:L42,"Listo") -> 21 | F3: Avance (horas listas / horas del backlog) | G3: =IF(C3=0,0,E3/C3) -> 0.05915493
A5: Prioridad | B5: ID | C5: Historia | D5: Historia de usuario | E5: Tipo | F5: Épica | G5: Requisito | H5: MoSCoW | I5: Dueño | J5: Horas | K5: Sprint | L5: Estado | M5: Fecha Listo | N5: Depende de | O5: Criterios del MVP | P5: Notas
A6: 1 | B6: HU-01 | C6: Sistema levantable con un comando | D6: Como equipo de desarrollo, queremos levantar el sistema completo con un solo comando, para que cualquiera pueda clonar el repositorio y trabajar sobre la misma base. | E6: Técnica | F6: EP-01 · Infraestructura | G6: RNF-05 | H6: Must | I6: Bryan | J6: 18 | K6: Cimientos | L6: Listo | M6: 46286 | N6: — | O6: CA8 | P6: Se fusionó el 21-09, primer día del sprint 1: se activó el disparador de R-02 y la respuesta prevista funcionó.
A7: 2 | B7: HU-02 | C7: Correo de desarrollo (Mailpit) | D7: Como equipo de desarrollo, queremos un servidor de correo de desarrollo dentro de la composición, para probar la verificación de cuentas y los avisos sin enviar correos a personas reales. | E7: Técnica | F7: EP-01 · Infraestructura | G7: AD-11 | H7: Must | I7: Bryan | J7: 3 | K7: Sprint 1 | L7: Listo | M7: 46290 | N7: HU-01 | O7: CA1 | P7: La prueba con una casilla real (supuesto S-02) sigue pendiente y vence el 04-10.
A8: 3 | B8: HU-03 | C8: Contrato OpenAPI de Identidad | D8: Como equipo de desarrollo, queremos el contrato OpenAPI de Identidad escrito y congelado al inicio del sprint, para que las pantallas y el servicio se construyan en paralelo contra la misma especificación. | E8: Técnica | F8: EP-09 · Calidad | G8: Pilar 2 §4 | H8: Must | I8: Bryan | J8: 4 | K8: Sprint 1 | L8: Por hacer | N8: HU-01 | P8: La carta Gantt la ubica el 23 y 24-09; al 27-09 no hay contrato en docs/api. Desde el 25-09 congela solo Identidad: en el sprint 1 nadie usa endpoints de Catálogo ni de Tutorías (Pilar 4, registro de decisiones).
A9: 4 | B9: HU-04 | C9: Registro y verificación del correo | D9: Como estudiante de Duoc UC, quiero registrarme con mi correo institucional y verificarlo desde el correo que recibo, para tener mi cuenta en la plataforma. | E9: Usuario | F9: EP-02 · Identidad y acceso | G9: RF-01 | H9: Must | I9: Bryan | J9: 10 | K9: Sprint 1 | L9: En revisión | N9: HU-02, HU-03 | O9: CA1 | P9: Al 01-10: rama feat/HU-04-registro-usuario, PR #5. Queda el modelo de Identidad, el registro y la verificación del correo.
A10: 5 | B10: HU-05 | C10: Inicio, renovación y cierre de sesión | D10: Como usuario verificado, quiero iniciar sesión, mantenerla activa y cerrarla, para usar la plataforma de forma segura. | E10: Usuario | F10: EP-02 · Identidad y acceso | G10: RF-01 | H10: Must | I10: Bryan | J10: 8 | K10: Sprint 1 | L10: En revisión | N10: HU-03, HU-04 | O10: CA1 | P10: Al 01-10: rama feat/HU-05-inicio-sesion, PR #11. Queda el inicio de sesión con token RS256, la renovación y el cierre de sesión.
A11: 6 | B11: HU-06 | C11: Base del frontend | D11: Como equipo de desarrollo, queremos la base del frontend en React con rutas, un cliente HTTP y una disposición común, para que cada dueño construya sus pantallas sobre la misma estructura. | E11: Técnica | F11: EP-01 · Infraestructura | G11: AD-12 | H11: Must | I11: Francisco | J11: 14 | K11: Sprint 1 | L11: En curso | N11: HU-01, HU-03 | O11: CA1 | P11: Al 01-10: rama feat/HU-06-paginas-en-gateway, PR #10. Quedan las páginas estáticas que sirve Nginx en /app/ (la alternativa de AD-12); la base en React no se hizo. La hizo Bryan por reasignación del 30-09. Tiene 14 h: al planificar se parte en dos ramas con un punto de integración intermedio (Pilar 4 §6).
A12: 7 | B12: HU-09 | C12: Pantallas de registro e inicio de sesión | D12: Como estudiante, quiero pantallas de registro e inicio de sesión simples y conectadas, para crear mi cuenta y entrar sin pasos innecesarios. | E12: Usuario | F12: EP-02 · Identidad y acceso | G12: RF-01 | H12: Must | I12: Damaris | J12: 12 | K12: Sprint 1 | L12: En revisión | N12: HU-03, HU-06 | O12: CA1 | P12: Al 01-10: rama feat/HU-09-pantallas-acceso, PR #12. Quedan registro.html, login.html y verificar.html conectados a Identidad. La hizo Bryan por reasignación del 30-09. Corrige las maquetas de la semana de planificación (Pilar 3 §13): pedían RUT, tipo de cuenta, carrera, sede y semestre, y validaban la contraseña con seis caracteres.
A13: 8 | B13: HU-08 | C13: Modelo de Tutorías y perfiles de tutor | D13: Como equipo de desarrollo, queremos el modelo de datos de Tutorías y los perfiles de tutor en el backend, para construir encima la declaración de asignaturas y la disponibilidad. | E13: Técnica | F13: EP-04 · Perfil de tutor y disponibilidad | G13: RF-03 | H13: Must | I13: Damaris | J13: 12 | K13: Sprint 1 | L13: En revisión | N13: HU-01 | O13: CA2 | P13: Al 01-10: rama feat/HU-08-modelo-tutorias, PR #7. Queda completa y los criterios 1 a 4 tienen pruebas. La hizo Bryan por reasignación del 30-09.
A14: 9 | B14: HU-07 | C14: Modelo del catálogo y carga desde CSV | D14: Como equipo de desarrollo, queremos el modelo del catálogo académico y un script de carga desde archivos CSV, para programar contra datos académicos reales desde el primer sprint. | E14: Técnica | F14: EP-03 · Catálogo académico | G14: RF-04 | H14: Must | I14: Francisco | J14: 8 | K14: Sprint 1 | L14: En curso | N14: HU-01 | O14: CA2 | P14: Al 01-10: rama feat/HU-07-modelo-catalogo, PR #6. Queda el modelo del catálogo, con ocho tablas; falta el script de carga desde CSV (criterios 2 a 4). La hizo Bryan por reasignación del 30-09.
A15: 10 | B15: HU-11 | C15: Pruebas de Identidad y contratos del sprint 2 | D15: Como equipo de desarrollo, queremos pruebas automatizadas de Identidad y los contratos del sprint 2 congelados, para proteger el registro y la sesión y trabajar en paralelo con Catálogo y Tutorías. | E15: Técnica | F15: EP-09 · Calidad | G15: RNF-06 | H15: Must | I15: Bryan | J15: 8 | K15: Sprint 2 | L15: Por hacer | N15: HU-04, HU-05 | O15: CA1 · CA2 | P15: Se parte en dos: los contratos el primer día del sprint y las pruebas en la segunda semana. Los contratos se escriben antes del 05-10, idealmente en la planificación del 04-10: nada se construye contra un contrato no escrito (A9).
A16: 11 | B16: HU-10 | C16: Perfil con carrera, nivel y sede | D16: Como usuario, quiero completar y editar mi perfil con carrera, nivel y sede, para poder ofrecer tutorías y que otros sepan dónde estudio. | E16: Usuario | F16: EP-02 · Identidad y acceso | G16: RF-02 | H16: Must | I16: Bryan | J16: 12 | K16: Sprint 2 | L16: Por hacer | N16: HU-05, HU-12 | O16: CA2
A17: 12 | B17: HU-12 | C17: Carreras, sedes, asignaturas y mallas (API) | D17: Como estudiante, quiero buscar asignaturas por nombre o sigla y ver la malla de mi carrera por semestre, para encontrar la asignatura en que necesito ayuda. | E17: Usuario | F17: EP-03 · Catálogo académico | G17: RF-04 | H17: Must | I17: Francisco | J17: 14 | K17: Sprint 2 | L17: En curso | N17: HU-07, HU-11 | O17: CA2 | P17: Al 01-10: rama feat/HU-12-api-catalogo, PR #9. Adelantada del sprint 2: quedan los GET públicos de Catálogo; faltan los /internal y la prueba de contrato. La rama sale de la de HU-07. La hizo Bryan por reasignación del 30-09. Tiene 14 h: se parte en dos ramas (listas y búsqueda; malla y endpoints internos).
A18: 13 | B18: HU-14 | C18: Declarar asignaturas con tarifa (RN-01) | D18: Como usuario con el perfil completo, quiero declarar las asignaturas que puedo tutorear con su tarifa, para ofrecer tutorías en lo que domino. | E18: Usuario | F18: EP-04 · Perfil de tutor y disponibilidad | G18: RF-03 · RN-01 | H18: Must | I18: Damaris | J18: 14 | K18: Sprint 2 | L18: Por hacer | N18: HU-08, HU-10, HU-12 | O18: CA2 | P18: Tiene 14 h: se parte en dos ramas (regla RN-01; copias de lectura y pantalla).
A19: 14 | B19: HU-15 | C19: Bloques de disponibilidad | D19: Como tutor, quiero publicar, editar y eliminar bloques de disponibilidad, para que los estudiantes sepan cuándo puedo hacer tutorías. | E19: Usuario | F19: EP-04 · Perfil de tutor y disponibilidad | G19: RF-05 | H19: Must | I19: Damaris | J19: 12 | K19: Sprint 2 | L19: Por hacer | N19: HU-08, HU-14 | O19: CA2
A20: 15 | B20: HU-13 | C20: Carga de 3 a 5 carreras | D20: Como estudiante de una carrera cargada, quiero que mi carrera y su malla estén en la plataforma, para declarar asignaturas y encontrar tutores de mi malla. | E20: Usuario | F20: EP-03 · Catálogo académico | G20: RF-04 | H20: Must | I20: Francisco | J20: 12 | K20: Sprint 2 | L20: Por hacer | N20: HU-07, HU-12 | O20: CA2
A21: 16 | B21: HU-19 | C21: Sincronización de copias de lectura | D21: Como equipo de desarrollo, queremos un comando que sincronice las copias de lectura de Tutorías, para que la búsqueda muestre datos vigentes y excluya las cuentas desactivadas. | E21: Técnica | F21: EP-05 · Búsqueda y reservas | G21: AD-07 · A-01 · A-13 | H21: Must | I21: Francisco | J21: 10 | K21: Sprint 2 | L21: Por hacer | N21: HU-11, HU-14 | O21: CA3 · CA7 | P21: En el Pilar 4 v1.6 estaba en el Sprint 3. Adelantada del sprint 3 al 2 en la replanificación. Se ejecuta a mano hasta que exista el contenedor programador (HU-37).
A22: 17 | B22: HU-21 | C22: Solicitar una tutoría | D22: Como estudiante, quiero solicitar una tutoría sobre un bloque disponible, con una nota opcional, para coordinar una sesión con el tutor. | E22: Usuario | F22: EP-05 · Búsqueda y reservas | G22: RF-07 · AD-07 | H22: Must | I22: Damaris | J22: 8 | K22: Sprint 2 | L22: Por hacer | N22: HU-11, HU-15 | O22: CA3 | P22: En el Pilar 4 v1.6 estaba en el Sprint 3. Adelantada del sprint 3 al 2 en la replanificación.
A23: 18 | B23: HU-16 | C23: Avisos por correo | D23: Como tutor, quiero recibir un correo cuando alguien me solicita una tutoría y, como estudiante, uno cuando me la confirman o rechazan, para enterarme sin revisar la plataforma a cada rato. | E23: Usuario | F23: EP-06 · Avisos | G23: RF-09 | H23: Must | I23: Bryan | J23: 10 | K23: Sprint 2 | L23: Por hacer | N23: HU-02, HU-11 | O23: CA3 · CA4 | P23: En el Pilar 4 v1.6 estaba en el Sprint 3. Adelantada del sprint 3 al 2 en la replanificación: se construye contra el contrato y se integra en el sprint 3.
A24: 19 | B24: HU-37 | C24: Contenedor programador | D24: Como equipo de desarrollo, queremos el contenedor programador en la composición, para que los comandos de Tutorías se ejecuten solos cada cinco minutos. | E24: Técnica | F24: EP-01 · Infraestructura | G24: AD-10 | H24: Must | I24: Bryan | J24: 3 | K24: Sprint 3 | L24: Por hacer | N24: HU-01, HU-19 | O24: CA6 | P24: En el Pilar 4 v1.6 estaba en el Sprint 4. Va los dos primeros días del sprint 3, antes de HU-29 (replanificación).
A25: 20 | B25: HU-20 | C25: Búsqueda de tutores con reputación | D25: Como estudiante, quiero buscar tutores por asignatura y ver su reputación, para elegir al tutor con mejores referencias. | E25: Usuario | F25: EP-05 · Búsqueda y reservas | G25: RF-06 | H25: Must | I25: Damaris | J25: 10 | K25: Sprint 3 | L25: Por hacer | N25: HU-14, HU-19 | O25: CA3 | P25: Puede adelantarse con la holgura del sprint 2 (replanificación).
A26: 21 | B26: HU-18 | C26: Pantallas de búsqueda y resultados | D26: Como estudiante, quiero buscar una asignatura y ver los tutores que la ofrecen, para elegir con quién pedir una tutoría. | E26: Usuario | F26: EP-05 · Búsqueda y reservas | G26: RF-06 | H26: Must | I26: Francisco | J26: 12 | K26: Sprint 3 | L26: Por hacer | N26: HU-06, HU-12, HU-20 | O26: CA3 | P26: Rehace la página de asignaturas de la semana de planificación sobre el contrato de Catálogo (Pilar 3 §13). Puede adelantarse con la holgura del sprint 2 (replanificación).
A27: 22 | B27: HU-22 | C27: Confirmar o rechazar una solicitud | D27: Como tutor, quiero confirmar o rechazar las solicitudes que recibo, para decidir con quién hago cada tutoría. | E27: Usuario | F27: EP-05 · Búsqueda y reservas | G27: RF-07 · RN-03 | H27: Must | I27: Damaris | J27: 12 | K27: Sprint 3 | L27: Por hacer | N27: HU-21 | O27: CA4
A28: 23 | B28: HU-23 | C28: Pagos simulados (servicio) | D28: Como estudiante, quiero pagar de forma simulada una tutoría confirmada y reintentar si falla, para dejar resuelto el pago de la sesión. | E28: Usuario | F28: EP-08 · Pagos | G28: RF-12 · RN-05 | H28: Must | I28: Bryan | J28: 12 | K28: Sprint 3 | L28: En curso | N28: HU-22 | O28: CA5 · CA9 | P28: Al 01-10: rama feat/HU-23-modelo-pagos, PR #8. Adelantada del sprint 3: queda solo el modelo de pago e intento_pago. En el Pilar 4 v1.6 estaba en el Sprint 4. Va en la primera semana del sprint 3, antes de HU-28 (cancelación con reembolso).
A29: 24 | B29: HU-28 | C29: Cancelación, retiro y expiración | D29: Como estudiante o tutor, quiero cancelar una reserva confirmada o retirar una solicitud pendiente, para liberar el horario cuando no podemos asistir. | E29: Usuario | F29: EP-05 · Búsqueda y reservas | G29: RF-08 · RN-04 | H29: Must | I29: Damaris | J29: 12 | K29: Sprint 3 | L29: Por hacer | N29: HU-22, HU-23 | O29: CA9 | P29: En el Pilar 4 v1.6 estaba en el Sprint 4.
A30: 25 | B30: HU-29 | C30: Cierre automático y expiración (programador) | D30: Como usuario, quiero que las tutorías pasen solas a realizadas cuando termina la hora y que las solicitudes sin respuesta expiren, para poder evaluar y no quedar con solicitudes pendientes para siempre. | E30: Usuario | F30: EP-05 · Búsqueda y reservas | G30: AD-10 | H30: Must | I30: Damaris | J30: 6 | K30: Sprint 3 | L30: Por hacer | N30: HU-28, HU-37 | O30: CA6 | P30: En el Pilar 4 v1.6 estaba en el Sprint 4.
A31: 26 | B31: HU-25 | C31: Evaluación y reputación | D31: Como estudiante, quiero evaluar al tutor después de la sesión con una nota y un comentario opcional, para que otros estudiantes conozcan su desempeño. | E31: Usuario | F31: EP-07 · Evaluaciones y reputación | G31: RF-11 · RN-06 | H31: Must | I31: Francisco | J31: 14 | K31: Sprint 3 | L31: Por hacer | N31: HU-22, HU-29 | O31: CA6 | P31: En el Pilar 4 v1.6 estaba en el Sprint 4. Tiene 14 h: se parte en dos ramas. Se desarrolla con reservas de prueba en estado REALIZADA; la demostración completa se hace al cierre, con HU-29 lista.
A32: 27 | B32: HU-26 | C32: Historial y pantalla de evaluación | D32: Como usuario, quiero ver el historial de las tutorías que solicité e impartí y evaluar desde ahí, para llevar registro de mis sesiones. | E32: Usuario | F32: EP-07 · Evaluaciones y reputación | G32: RF-10 · RF-11 | H32: Must | I32: Francisco | J32: 8 | K32: Sprint 3 | L32: Por hacer | N32: HU-06, HU-25 | O32: CA6 | P32: En el Pilar 4 v1.6 estaba en el Sprint 4. Conviene delimitarla con HU-30: el historial muestra lo terminado y «Mis reservas» lo vigente.
A33: 28 | B33: HU-24 | C33: Pantalla de pago y estado del pago | D33: Como estudiante, quiero una pantalla de pago simulado y ver el estado del pago en el detalle de la reserva, para saber si la tutoría quedó pagada. | E33: Usuario | F33: EP-08 · Pagos | G33: RF-12 | H33: Must | I33: Bryan | J33: 4 | K33: Sprint 3 | L33: Por hacer | N33: HU-23 | O33: CA5 | P33: En el Pilar 4 v1.6 estaba en el Sprint 4. Si el 27-10 el sprint 3 va atrasado y ya se aplicó el escalón 3, el escalón 4 saca esta historia (sin pago simulado), previa consulta al profesor.
A34: 29 | B34: HU-30 | C34: Mis reservas y solicitudes recibidas | D34: Como usuario, quiero ver mis reservas y las solicitudes que recibo, para gestionar mis tutorías desde un solo lugar. | E34: Usuario | F34: EP-05 · Búsqueda y reservas | G34: RF-10 | H34: Must | I34: Bryan | J34: 6 | K34: Sprint 3 | L34: Por hacer | N34: HU-21, HU-22, HU-24, HU-28 | O34: CA4 · CA9 | P34: En el Pilar 4 v1.6 estaba en el Sprint 4. Dueño en el Pilar 4: Damaris (cambio a acordar). La replanificación la pasa de Damaris a Bryan (a acordar con el equipo). El backend sigue siendo de Damaris.
A35: 30 | B35: HU-17 | C35: Integración de Identidad y sus pruebas | D35: Como equipo de desarrollo, queremos integrar Identidad con el resto de los servicios y probar esa integración, para asegurar que tokens, datos internos y avisos funcionen entre servicios. | E35: Técnica | F35: EP-09 · Calidad | G35: RNF-06 | H35: Must | I35: Bryan | J35: 4 | K35: Sprint 3 | L35: Por hacer | N35: HU-16, HU-21, HU-22 | O35: CA3 · CA4
A36: 31 | B36: HU-27 | C36: Pruebas de evaluaciones y reputación | D36: Como equipo de desarrollo, queremos pruebas automáticas del módulo de evaluaciones, para que RN-06 no se rompa sin que nadie lo note. | E36: Técnica | F36: EP-09 · Calidad | G36: RNF-06 | H36: Must | I36: Francisco | J36: 6 | K36: Sprint 3 | L36: Por hacer | N36: HU-25 | O36: CA6 | P36: En el Pilar 4 v1.6 estaba en el Sprint 4.
A37: 32 | B37: HU-31 | C37: Administración de usuarios (Identidad) | D37: Como administrador, quiero listar usuarios y desactivar una cuenta, para operar y moderar la plataforma. | E37: Usuario | F37: EP-02 · Identidad y acceso | G37: RF-13 | H37: Must | I37: Bryan | J37: 6 | K37: Sprint 4 | L37: Por hacer | N37: HU-05 | O37: CA7 | P37: En el Pilar 4 v1.6 estaba en el Sprint 5. Va el lunes y martes del sprint 4, porque el panel (HU-33) depende de estos endpoints.
A38: 33 | B38: HU-33 | C38: Panel de administración | D38: Como administrador, quiero un panel para gestionar usuarios, tutorías, evaluaciones y el catálogo, para operar la plataforma sin tocar la base de datos. | E38: Usuario | F38: EP-02 · Identidad y acceso | G38: RF-13 | H38: Must | I38: Francisco | J38: 19 | K38: Sprint 4 | L38: Por hacer | N38: HU-12, HU-25, HU-31 | O38: CA7 | P38: En el Pilar 4 v1.6 estaba en el Sprint 5. Tiene 19 h: se parte en dos ramas. Si el 18-10 el sprint 2 cerró bajo el 90 %, se aplica el escalón 3 y el panel queda en consultar y desactivar usuarios (unas 6 h).
A39: 34 | B39: HU-34 | C39: Pruebas de extremo a extremo | D39: Como equipo de desarrollo, queremos pruebas de extremo a extremo sobre el sistema levantado, para demostrar que el recorrido completo funciona entre servicios. | E39: Técnica | F39: EP-09 · Calidad | G39: RNF-06 · RNF-02 | H39: Must | I39: Bryan | J39: 8 | K39: Sprint 4 | L39: Por hacer | N39: Todo el flujo del MVP | O39: CA8 | P39: En el Pilar 4 v1.6 estaba en el Sprint 5. Dueño en el Pilar 4: Francisco (cambio a acordar). La replanificación la pasa de Francisco a Bryan (a acordar con el equipo).
A40: 35 | B40: HU-36 | C40: Pruebas de Tutorías y corrección de errores | D40: Como equipo de desarrollo, queremos pruebas automáticas de Tutorías y corregir los errores de la integración, para que las reglas de negocio no se rompan. | E40: Técnica | F40: EP-09 · Calidad | G40: RNF-06 · RNF-08 | H40: Must | I40: Damaris | J40: 10 | K40: Sprint 4 | L40: Por hacer | N40: Tutorías completo | O40: CA8 | P40: En el Pilar 4 v1.6 estaba en el Sprint 5.
A41: 36 | B41: HU-35 | C41: Sistema visual y revisión en teléfono | D41: Como usuario, quiero que todas las pantallas se vean y funcionen bien en mi teléfono y en mi navegador, para usar la plataforma desde donde esté. | E41: Usuario | F41: EP-09 · Calidad | G41: RNF-03 · RNF-04 | H41: Must | I41: Damaris | J41: 8 | K41: Sprint 4 | L41: Por hacer | N41: Todas las pantallas | O41: CA8 | P41: En el Pilar 4 v1.6 estaba en el Sprint 5.
...

Sheet Resumen
A1: Resumen del backlog
A2: Todo se calcula desde la hoja Product Backlog: al cambiar un estado, un dueño o un sprint, estas tablas se actualizan solas.
A4: 1. Horas por sprint y dueño
A5: Sprint | B5: Bryan | C5: Francisco | D5: Damaris | E5: Total | F5: Listas | G5: Pendientes | H5: % listo
A6: Cimientos | B6: =SUMIFS('Product Backlog'!$J$6:$J$42,'Product Backlog'!$K$6:$K$42,$A6,'Product Backlog'!$I$6:$I$42,B$5) -> 18 | C6: =SUMIFS('Product Backlog'!$J$6:$J$42,'Product Backlog'!$K$6:$K$42,$A6,'Product Backlog'!$I$6:$I$42,C$5) -> 0 | D6: =SUMIFS('Product Backlog'!$J$6:$J$42,'Product Backlog'!$K$6:$K$42,$A6,'Product Backlog'!$I$6:$I$42,D$5) -> 0 | E6: =SUM(B6:D6) -> 18 | F6: =SUMIFS('Product Backlog'!$J$6:$J$42,'Product Backlog'!$K$6:$K$42,$A6,'Product Backlog'!$L$6:$L$42,"Listo") -> 18 | G6: =E6-F6 -> 0 | H6: =IF(E6=0,0,F6/E6) -> 1
A7: Sprint 1 | B7: =SUMIFS('Product Backlog'!$J$6:$J$42,'Product Backlog'!$K$6:$K$42,$A7,'Product Backlog'!$I$6:$I$42,B$5) -> 25 | C7: =SUMIFS('Product Backlog'!$J$6:$J$42,'Product Backlog'!$K$6:$K$42,$A7,'Product Backlog'!$I$6:$I$42,C$5) -> 22 | D7: =SUMIFS('Product Backlog'!$J$6:$J$42,'Product Backlog'!$K$6:$K$42,$A7,'Product Backlog'!$I$6:$I$42,D$5) -> 24 | E7: =SUM(B7:D7) -> 71 | F7: =SUMIFS('Product Backlog'!$J$6:$J$42,'Product Backlog'!$K$6:$K$42,$A7,'Product Backlog'!$L$6:$L$42,"Listo") -> 3 | G7: =E7-F7 -> 68 | H7: =IF(E7=0,0,F7/E7) -> 0.042253521
A8: Sprint 2 | B8: =SUMIFS('Product Backlog'!$J$6:$J$42,'Product Backlog'!$K$6:$K$42,$A8,'Product Backlog'!$I$6:$I$42,B$5) -> 30 | C8: =SUMIFS('Product Backlog'!$J$6:$J$42,'Product Backlog'!$K$6:$K$42,$A8,'Product Backlog'!$I$6:$I$42,C$5) -> 36 | D8: =SUMIFS('Product Backlog'!$J$6:$J$42,'Product Backlog'!$K$6:$K$42,$A8,'Product Backlog'!$I$6:$I$42,D$5) -> 34 | E8: =SUM(B8:D8) -> 100 | F8: =SUMIFS('Product Backlog'!$J$6:$J$42,'Product Backlog'!$K$6:$K$42,$A8,'Product Backlog'!$L$6:$L$42,"Listo") -> 0 | G8: =E8-F8 -> 100 | H8: =IF(E8=0,0,F8/E8) -> 0
A9: Sprint 3 | B9: =SUMIFS('Product Backlog'!$J$6:$J$42,'Product Backlog'!$K$6:$K$42,$A9,'Product Backlog'!$I$6:$I$42,B$5) -> 29 | C9: =SUMIFS('Product Backlog'!$J$6:$J$42,'Product Backlog'!$K$6:$K$42,$A9,'Product Backlog'!$I$6:$I$42,C$5) -> 40 | D9: =SUMIFS('Product Backlog'!$J$6:$J$42,'Product Backlog'!$K$6:$K$42,$A9,'Product Backlog'!$I$6:$I$42,D$5) -> 40 | E9: =SUM(B9:D9) -> 109 | F9: =SUMIFS('Product Backlog'!$J$6:$J$42,'Product Backlog'!$K$6:$K$42,$A9,'Product Backlog'!$L$6:$L$42,"Listo") -> 0 | G9: =E9-F9 -> 109 | H9: =IF(E9=0,0,F9/E9) -> 0
A10: Sprint 4 | B10: =SUMIFS('Product Backlog'!$J$6:$J$42,'Product Backlog'!$K$6:$K$42,$A10,'Product Backlog'!$I$6:$I$42,B$5) -> 14 | C10: =SUMIFS('Product Backlog'!$J$6:$J$42,'Product Backlog'!$K$6:$K$42,$A10,'Product Backlog'!$I$6:$I$42,C$5) -> 19 | D10: =SUMIFS('Product Backlog'!$J$6:$J$42,'Product Backlog'!$K$6:$K$42,$A10,'Product Backlog'!$I$6:$I$42,D$5) -> 18 | E10: =SUM(B10:D10) -> 51 | F10: =SUMIFS('Product Backlog'!$J$6:$J$42,'Product Backlog'!$K$6:$K$42,$A10,'Product Backlog'!$L$6:$L$42,"Listo") -> 0 | G10: =E10-F10 -> 51 | H10: =IF(E10=0,0,F10/E10) -> 0
A11: Sem. 14–15 | B11: =SUMIFS('Product Backlog'!$J$6:$J$42,'Product Backlog'!$K$6:$K$42,$A11,'Product Backlog'!$I$6:$I$42,B$5) -> 6 | C11: =SUMIFS('Product Backlog'!$J$6:$J$42,'Product Backlog'!$K$6:$K$42,$A11,'Product Backlog'!$I$6:$I$42,C$5) -> 0 | D11: =SUMIFS('Product Backlog'!$J$6:$J$42,'Product Backlog'!$K$6:$K$42,$A11,'Product Backlog'!$I$6:$I$42,D$5) -> 0 | E11: =SUM(B11:D11) -> 6 | F11: =SUMIFS('Product Backlog'!$J$6:$J$42,'Product Backlog'!$K$6:$K$42,$A11,'Product Backlog'!$L$6:$L$42,"Listo") -> 0 | G11: =E11-F11 -> 6 | H11: =IF(E11=0,0,F11/E11) -> 0
A12: Total | B12: =SUM(B6:B11) -> 122 | C12: =SUM(C6:C11) -> 117 | D12: =SUM(D6:D11) -> 116 | E12: =SUM(E6:E11) -> 355 | F12: =SUM(F6:F11) -> 21 | G12: =SUM(G6:G11) -> 334 | H12: =IF(E12=0,0,F12/E12) -> 0.05915493
A14: 2. Planificado frente a capacidad de desarrollo (replanificación, 25 h semanales)
A15: Sprint | B15: Bryan | C15: Capacidad | D15: Francisco | E15: Capacidad | F15: Damaris | G15: Capacidad | H15: Total | I15: Capacidad | J15: Diferencia
A16: Sprint 2 | B16: =B8 -> 30 | C16: 29.5 | D16: =C8 -> 36 | E16: 37.5 | F16: =D8 -> 34 | G16: 37.5 | H16: =B16+D16+F16 -> 100 | I16: =C16+E16+G16 -> 104.5 | J16: =I16-H16 -> 4.5
A17: Sprint 3 | B17: =B9 -> 29 | C17: 29.5 | D17: =C9 -> 40 | E17: 37.5 | F17: =D9 -> 40 | G17: 37.5 | H17: =B17+D17+F17 -> 109 | I17: =C17+E17+G17 -> 104.5 | J17: =I17-H17 -> -4.5
A18: Sprint 4 | B18: =B10 -> 14 | C18: 14.75 | D18: =C10 -> 19 | E18: 18.75 | F18: =D10 -> 18 | G18: 18.75 | H18: =B18+D18+F18 -> 51 | I18: =C18+E18+G18 -> 52.25 | J18: =I18-H18 -> 1.25
A19: Capacidad (en azul): replanificación del 25-09, con 14,75 h de desarrollo por semana para Bryan y 18,75 h para Francisco y Damaris. Una diferencia negativa (en rojo) significa horas planificadas por sobre la capacidad. El sprint 1 se planificó con el Pilar 4 v1.6 (20 h semanales); desde el 26-09 le quedan 68 h frente a 67,2 h de capacidad.
A22: 3. Horas por épica
A23: Épica | B23: Historias | C23: Horas | D23: Horas listas | E23: % avance
A24: EP-01 · Infraestructura | B24: =COUNTIF('Product Backlog'!$F$6:$F$42,$A24) -> 4 | C24: =SUMIFS('Product Backlog'!$J$6:$J$42,'Product Backlog'!$F$6:$F$42,$A24) -> 38 | D24: =SUMIFS('Product Backlog'!$J$6:$J$42,'Product Backlog'!$F$6:$F$42,$A24,'Product Backlog'!$L$6:$L$42,"Listo") -> 21 | E24: =IF(C24=0,0,D24/C24) -> 0.55263158
A25: EP-02 · Identidad y acceso | B25: =COUNTIF('Product Backlog'!$F$6:$F$42,$A25) -> 6 | C25: =SUMIFS('Product Backlog'!$J$6:$J$42,'Product Backlog'!$F$6:$F$42,$A25) -> 67 | D25: =SUMIFS('Product Backlog'!$J$6:$J$42,'Product Backlog'!$F$6:$F$42,$A25,'Product Backlog'!$L$6:$L$42,"Listo") -> 0 | E25: =IF(C25=0,0,D25/C25) -> 0
A26: EP-03 · Catálogo académico | B26: =COUNTIF('Product Backlog'!$F$6:$F$42,$A26) -> 3 | C26: =SUMIFS('Product Backlog'!$J$6:$J$42,'Product Backlog'!$F$6:$F$42,$A26) -> 34 | D26: =SUMIFS('Product Backlog'!$J$6:$J$42,'Product Backlog'!$F$6:$F$42,$A26,'Product Backlog'!$L$6:$L$42,"Listo") -> 0 | E26: =IF(C26=0,0,D26/C26) -> 0
A27: EP-04 · Perfil de tutor y disponibilidad | B27: =COUNTIF('Product Backlog'!$F$6:$F$42,$A27) -> 3 | C27: =SUMIFS('Product Backlog'!$J$6:$J$42,'Product Backlog'!$F$6:$F$42,$A27) -> 38 | D27: =SUMIFS('Product Backlog'!$J$6:$J$42,'Product Backlog'!$F$6:$F$42,$A27,'Product Backlog'!$L$6:$L$42,"Listo") -> 0 | E27: =IF(C27=0,0,D27/C27) -> 0
A28: EP-05 · Búsqueda y reservas | B28: =COUNTIF('Product Backlog'!$F$6:$F$42,$A28) -> 8 | C28: =SUMIFS('Product Backlog'!$J$6:$J$42,'Product Backlog'!$F$6:$F$42,$A28) -> 76 | D28: =SUMIFS('Product Backlog'!$J$6:$J$42,'Product Backlog'!$F$6:$F$42,$A28,'Product Backlog'!$L$6:$L$42,"Listo") -> 0 | E28: =IF(C28=0,0,D28/C28) -> 0
A29: EP-06 · Avisos | B29: =COUNTIF('Product Backlog'!$F$6:$F$42,$A29) -> 1 | C29: =SUMIFS('Product Backlog'!$J$6:$J$42,'Product Backlog'!$F$6:$F$42,$A29) -> 10 | D29: =SUMIFS('Product Backlog'!$J$6:$J$42,'Product Backlog'!$F$6:$F$42,$A29,'Product Backlog'!$L$6:$L$42,"Listo") -> 0 | E29: =IF(C29=0,0,D29/C29) -> 0
A30: EP-07 · Evaluaciones y reputación | B30: =COUNTIF('Product Backlog'!$F$6:$F$42,$A30) -> 2 | C30: =SUMIFS('Product Backlog'!$J$6:$J$42,'Product Backlog'!$F$6:$F$42,$A30) -> 22 | D30: =SUMIFS('Product Backlog'!$J$6:$J$42,'Product Backlog'!$F$6:$F$42,$A30,'Product Backlog'!$L$6:$L$42,"Listo") -> 0 | E30: =IF(C30=0,0,D30/C30) -> 0
A31: EP-08 · Pagos | B31: =COUNTIF('Product Backlog'!$F$6:$F$42,$A31) -> 2 | C31: =SUMIFS('Product Backlog'!$J$6:$J$42,'Product Backlog'!$F$6:$F$42,$A31) -> 16 | D31: =SUMIFS('Product Backlog'!$J$6:$J$42,'Product Backlog'!$F$6:$F$42,$A31,'Product Backlog'!$L$6:$L$42,"Listo") -> 0 | E31: =IF(C31=0,0,D31/C31) -> 0
A32: EP-09 · Calidad | B32: =COUNTIF('Product Backlog'!$F$6:$F$42,$A32) -> 8 | C32: =SUMIFS('Product Backlog'!$J$6:$J$42,'Product Backlog'!$F$6:$F$42,$A32) -> 54 | D32: =SUMIFS('Product Backlog'!$J$6:$J$42,'Product Backlog'!$F$6:$F$42,$A32,'Product Backlog'!$L$6:$L$42,"Listo") -> 0 | E32: =IF(C32=0,0,D32/C32) -> 0
A33: Total | B33: =SUM(B24:B32) -> 37 | C33: =SUM(C24:C32) -> 355 | D33: =SUM(D24:D32) -> 21 | E33: =IF(C33=0,0,D33/C33) -> 0.05915493
A35: 4. Historias por tipo
A36: Tipo | B36: Historias | C36: Horas
A37: Usuario | B37: =COUNTIF('Product Backlog'!$E$6:$E$42,$A37) -> 23 | C37: =SUMIFS('Product Backlog'!$J$6:$J$42,'Product Backlog'!$E$6:$E$42,$A37) -> 241
A38: Técnica | B38: =COUNTIF('Product Backlog'!$E$6:$E$42,$A38) -> 13 | C38: =SUMIFS('Product Backlog'!$J$6:$J$42,'Product Backlog'!$E$6:$E$42,$A38) -> 108
A39: Tarea del proyecto | B39: =COUNTIF('Product Backlog'!$E$6:$E$42,$A39) -> 1 | C39: =SUMIFS('Product Backlog'!$J$6:$J$42,'Product Backlog'!$E$6:$E$42,$A39) -> 6
A40: Total | B40: =SUM(B37:B39) -> 37 | C40: =SUM(C37:C39) -> 355

Sheet Leyenda
A1: Leyenda
A3: Cómo usar esta planilla
A4: Orden | B4: La columna Prioridad es el orden del backlog: por sprint y, dentro de cada sprint, por dependencias y por aporte al objetivo del sprint. Para repriorizar, cambia los números y ordena la tabla por esa columna.
A5: Estado | B5: Por hacer · En curso · En revisión (Pull Request abierto) · Listo. Una historia pasa a Listo solo si cumple la definición de Listo del Pilar 5 §8, incluida la fusión a develop.
A6: Fecha Listo | B6: Día en que la historia se fusionó a develop. La usan los burndown de cada sprint.
A7: Sprint y Dueño | B7: Según la replanificación del 25-09, a acordar con el equipo. La columna Notas dice cuándo difieren del Pilar 4 v1.6.
A8: Horas | B8: Estimación en horas del Pilar 4 v1.6 (en azul: valores escritos a mano). Toda historia sobre 12 h se parte en dos ramas al planificar.
A9: MoSCoW | B9: Las 37 historias son Must. Los candidatos Should y Could están abajo, sin sprint.
A10: Criterios del MVP | B10: Criterios de aceptación del Pilar 1 (CA1 a CA9) que la historia ayuda a demostrar. Los criterios de cada historia están en el documento 7.
A11: Colores | B11: Verde: Listo. Amarillo: En curso. Celeste: En revisión. Azul en el texto: número escrito a mano.
A13: Fuentes
A14: Historias y horas | B14: Pilar 4 v1.6, tabla 3.2, y carta Gantt (columna Épica).
A15: Sprints y dueños | B15: Replanificación del 25-09-2026 (propuesta del líder).
A16: Estados | B16: Repositorio al 27-09-2026: HU-01 (PR #1, 21-09) y HU-02 (PR #2, 25-09) fusionadas a develop; sin ramas de HU-03 a HU-09 en GitHub. HU-04 a HU-09, HU-12 y HU-23: estado al 01-10-2026 informado por Bryan (ver Notas); ningún PR se fusionó.
